Workbook
Name corrected_dates: 'Transactions (Cleaned)'!$A$1:$K$10178

Sheet Transactions Overview
A1: transaction_id | B1: transaction_date | C1: account_type | D1: branch_city | E1: branch_state | F1: amount | G1: transaction_type | H1: category | I1: merchant | J1: payment_method | K1: status
A2: 106499 | B2: 45992 | C2: Money Market | D2: Albany | E2: NY | F2: -2282.09 | G2: Payment | H2: transportation | I2: EZ-Pass | J2: WIRE | K2: Completed
A3: 101635 | B3: 45715 | C3: savings | D3: Philadelphia | E3: Pennsylvania | F3: 431.86 | G3: Transfer | H3: transportation | I3: Lyft | K3: Pending
A4: 102938 | B4: 45443 | C4: Checking | D4: Stamford | E4: Connecticut | F4: 277.69 | G4: Transfer | H4: Shopping | I4: Amazon | J4: cash | K4: Completed
A5: 102938 | B5: 45443 | C5: Checking | D5: Stamford | E5: Connecticut | F5: 277.69 | G5: Transfer | H5: Shopping | I5: Amazon | J5: cash | K5: Completed
A6: 110478 | B6: 44762 | C6: credit card | D6: New York | E6: New York | F6: 2999.37 | G6: Transfer | H6: SHOPPING | I6: Target | J6: cash | K6: Completed
A7: 100906 | B7: 45254 | C7: savings | D7: Hartford | E7: CT | F7: -1087.05 | G7: Withdrawal | H7: fees | I7: Late Fee | J7: CASH | K7: Completed
A8: 104027 | B8: 45903 | C8: money market | D8: Jersey City | E8: New Jersey | F8: -102.75 | G8: Withdrawal | H8: Utility | I8: PSEG | J8: debit card | K8: Pending
A9: 105516 | B9: 45794 | C9: Credit Card | D9: New York | E9: NY | F9: -1605.73 | G9: Fee | H9: Rent | I9: Rent Payment | J9: cash | K9: Completed
A10: 108794 | B10: 45906 | C10: credit card | D10: Newark | E10: New Jersey | F10: 486.99 | G10: Deposit | H10: FEES | I10: Late Fee | J10: debit card | K10: Completed
A11: 107911 | B11: 44687 | C11: CHECKING | D11: Philadelphia | E11: Pennsylvania | F11: -1844.79 | G11: Payment | H11: Fee | I11: Late Fee | J11: CASH | K11: Completed
A12: 105279 | B12: 45774 | C12: money market | D12: Hicksville | E12: New York | F12: -2495.04 | G12: Withdrawal | H12: utilities | I12: National Grid | J12: Cash | K12: Completed
A13: 108373 | B13: 45968 | C13: Credit Card | D13: Boston | E13: MA | F13: 3060.68 | G13: Deposit | H13: Groceries | I13: Stop & Shop | J13: wire | K13: Completed
A14: 102618 | B14: 45346 | C14: Credit_Card | D14: Trenton | E14: New Jersey | F14: 2562.89 | G14: Transfer | H14: entertainment | I14: Hulu | J14: Cash | K14: Completed
A15: 102618 | B15: 45346 | C15: Credit_Card | D15: Trenton | E15: New Jersey | F15: 2562.89 | G15: Transfer | H15: entertainment | I15: Hulu | J15: Cash | K15: Completed
... A24: 107600 | B24: 45211 | C24: Money Market | D24: Albany | E24: New York | F24: 1954.44 | G24: Deposit | H24: Dining | I24: Starbucks | J24: Check | K24: Completed
A25: 100828 | B25: 24/04/2022 | C25: SAVINGS | D25: New York | E25: NY | F25: -1624.61 | G25: Fee | H25: Fee | I25: Late Fee | J25: ACH | K25: Completed
A26: 102560 | B26: 46230 | C26: money market | D26: BROOKLYN | E26: NY | F26: -430.51 | G26: Payment | H26: dining | I26: Starbucks | J26: CHECK | K26: Completed
A27: 102686 | B27: 45468 | C27: money market | D27: Jersey City | E27: NJ | F27: -842.49 | G27: Payment | H27: ENTERTAINMENT | I27: Hulu | J27: Check | K27: Completed
A28: 100504 | B28: 46056 | C28: Checking | D28: Boston | E28: Massachusetts | F28: -1531.07 | G28: Fee | H28: SHOPPING | I28: Best Buy | J28: Debit Card | K28: Completed
A29: 104092 | B29: 45008 | C29: Checking | D29: Trenton | E29: NJ | F29: -647.3 | G29: Withdrawal | H29: Transportation | I29: Shell Gas Station | J29: ach | K29: Completed
A30: 106340 | B30: 45341 | C30: money market | D30: Trenton | E30: New Jersey | F30: 118.5 | G30: Deposit | H30: Dining | I30: Chipotle | J30: credit card | K30: Completed
A31: 106340 | B31: 45341 | C31: money market | D31: Trenton | E31: New Jersey | F31: 118.5 | G31: Deposit | H31: Dining | I31: Chipotle | J31: credit card | K31: Completed
A32: 105305 | B32: 45571 | C32: checking | D32: Boston | E32: Massachusetts | F32: -821.76 | G32: Payment | H32: Entertainment | I32: Steam | K32: Completed
A33: 108240 | B33: 46117 | C33: money market | D33: Philadelphia | E33: PA | F33: -1601.03 | G33: Payment | H33: entertainment | I33: Netflix | J33: Cheque | K33: Completed
A34: 100840 | B34: 44690 | C34: CREDIT CARD | D34: Trenton | E34: New Jersey | F34: -219.92 | G34: Withdrawal | H34: Dining | I34: Chipotle | J34: ACH | K34: Completed
A35: 100840 | B35: 44690 | C35: CREDIT CARD | D35: Trenton | E35: New Jersey | F35: -219.92 | G35: Withdrawal | H35: Dining | I35: Chipotle | J35: ACH | K35: Completed
A36: 108931 | B36: 45608 | C36: Savings | D36: Philadelphia | E36: PA | F36: -685.09 | G36: Payment | H36: Shopping | I36: Walmart | J36: wire | K36: Completed
A37: 101832 | B37: 44974 | C37: money market | D37: Albany | E37: NY | F37: -326.64 | G37: Withdrawal | H37: HEALTHCARE | I37: Walgreens | J37: ACH | K37: Pending
A38: 105588 | B38: 44671 | C38: CHECKING | D38: Albany | E38: NY | F38: -2788.39 | G38: Payment | H38: insurance | I38: State Farm | J38: ach | K38: Completed
A39: 101703 | B39: 45556 | C39: Credit_Card | D39: New York | E39: New York | F39: -2600.4 | G39: Payment | H39: shopping | I39: Target | J39: Debit | K39: Completed
A40: 102630 | B40: 44912 | C40: credit card | D40: Philadelphia | E40: Pennsylvania | F40: -2251.77 | G40: Fee | H40: Fee | I40: ATM Fee | J40: Credit Card | K40: Completed
A41: 108467 | B41: 44984 | C41: money market | D41: Albany | E41: NY | F41: -964.9 | G41: Withdrawal | H41: Healthcare | I41: Copay - Dr. Visit | J41: Wire Transfer | K41: Completed
A42: 107547 | B42: 46077 | C42: CREDIT CARD | D42: Trenton | E42: New Jersey | F42: -2840.57 | G42: Payment | H42: Transfer | I42: Zelle Transfer | J42: cash | K42: Completed
A43: 107547 | B43: 46077 | C43: CREDIT CARD | D43: Trenton | E43: New Jersey | F43: -2840.57 | G43: Payment | H43: Transfer | I43: Zelle Transfer | J43: cash | K43: Completed
A44: 100499 | B44: 46178 | C44: money market | D44: Albany | E44: NY | F44: -393.53 | G44: Payment | H44: insurance | I44: Geico | J44: WIRE | K44: Completed
... A52: 110053 | B52: 45964 | C52: Credit Card | D52: Philadelphia | E52: PA | F52: 2591.34 | G52: Deposit | H52: transfer | I52: Venmo | J52: CHECK | K52: Completed
A53: 105509 | B53: 21/04/2025 | C53: savings | D53: White Plains | E53: New York | F53: 1492.32 | G53: Deposit | H53: Entertainment | I53: Netflix | J53: debit card | K53: Completed
A54: 108451 | B54: 46123 | C54: Money Market | D54: Brooklyn | E54: New York | F54: 2817.36 | G54: Transfer | H54: UTILITIES | I54: Verizon Fios | J54: ach | K54: Pending
A55: 109805 | B55: 45867 | C55: MoneyMarket | D55: Albany | E55: NY | F55: 3055.5 | G55: Transfer | H55: Health Care | I55: Copay - Dr. Visit | J55: check | K55: Completed
...

Sheet Transactions Overview (2)
A1: transaction_id | B1: transaction_date | C1: account_type | D1: branch_city | E1: branch_state | F1: amount | G1: transaction_type | H1: category | I1: merchant | J1: payment_method | K1: status
A2: 106499 | B2: 45992 | C2: =PROPER('Transactions Overview'!C2) -> Money Market | D2: =PROPER('Transactions Overview'!D2) -> Albany | E2: New York | F2: =ABS('Transactions Overview'!F2) -> 2282.09 | G2: Payment | H2: =PROPER('Transactions Overview'!H2) -> Transportation | I2: EZ-Pass | J2: Wire Transfer | K2: Completed
A3: 101635 | B3: 45715 | C3: =PROPER('Transactions Overview'!C3) -> Savings | D3: =PROPER('Transactions Overview'!D3) -> Philadelphia | E3: Pennsylvania | F3: =ABS('Transactions Overview'!F3) -> 431.86 | G3: Transfer | H3: =PROPER('Transactions Overview'!H3) -> Transportation | I3: Lyft | J3: =PROPER('Transactions Overview'!J3) | K3: Pending
A4: 102938 | B4: 45443 | C4: =PROPER('Transactions Overview'!C4) -> Checking | D4: =PROPER('Transactions Overview'!D4) -> Stamford | E4: Connecticut | F4: =ABS('Transactions Overview'!F4) -> 277.69 | G4: Transfer | H4: =PROPER('Transactions Overview'!H4) -> Shopping | I4: Amazon | J4: =PROPER('Transactions Overview'!J4) -> Cash | K4: Completed
A5: 110478 | B5: 44762 | C5: =PROPER('Transactions Overview'!C6) -> Credit Card | D5: =PROPER('Transactions Overview'!D6) -> New York | E5: New York | F5: =ABS('Transactions Overview'!F6) -> 2999.37 | G5: Transfer | H5: =PROPER('Transactions Overview'!H6) -> Shopping | I5: Target | J5: =PROPER('Transactions Overview'!J6) -> Cash | K5: Completed
A6: 100906 | B6: 45254 | C6: =PROPER('Transactions Overview'!C7) -> Savings | D6: =PROPER('Transactions Overview'!D7) -> Hartford | E6: Connecticut | F6: =ABS('Transactions Overview'!F7) -> 1087.05 | G6: Withdrawal | H6: =PROPER('Transactions Overview'!H7) -> Fees | I6: Late Fee | J6: =PROPER('Transactions Overview'!J7) -> Cash | K6: Completed
A7: 104027 | B7: 45903 | C7: =PROPER('Transactions Overview'!C8) -> Money Market | D7: =PROPER('Transactions Overview'!D8) -> Jersey City | E7: New Jersey | F7: =ABS('Transactions Overview'!F8) -> 102.75 | G7: Withdrawal | H7: Utilities | I7: PSEG | J7: =PROPER('Transactions Overview'!J8) -> Debit Card | K7: Pending
A8: 105516 | B8: 45794 | C8: =PROPER('Transactions Overview'!C9) -> Credit Card | D8: =PROPER('Transactions Overview'!D9) -> New York | E8: New York | F8: =ABS('Transactions Overview'!F9) -> 1605.73 | G8: Fee | H8: =PROPER('Transactions Overview'!H9) -> Rent | I8: Rent Payment | J8: =PROPER('Transactions Overview'!J9) -> Cash | K8: Completed
A9: 108794 | B9: 45906 | C9: =PROPER('Transactions Overview'!C10) -> Credit Card | D9: =PROPER('Transactions Overview'!D10) -> Newark | E9: New Jersey | F9: =ABS('Transactions Overview'!F10) -> 486.99 | G9: Deposit | H9: =PROPER('Transactions Overview'!H10) -> Fees | I9: Late Fee | J9: =PROPER('Transactions Overview'!J10) -> Debit Card | K9: Completed
A10: 107911 | B10: 44687 | C10: =PROPER('Transactions Overview'!C11) -> Checking | D10: =PROPER('Transactions Overview'!D11) -> Philadelphia | E10: Pennsylvania | F10: =ABS('Transactions Overview'!F11) -> 1844.79 | G10: Payment | H10: Fees | I10: Late Fee | J10: =PROPER('Transactions Overview'!J11) -> Cash | K10: Completed
A11: 105279 | B11: 45774 | C11: =PROPER('Transactions Overview'!C12) -> Money Market | D11: =PROPER('Transactions Overview'!D12) -> Hicksville | E11: New York | F11: =ABS('Transactions Overview'!F12) -> 2495.04 | G11: Withdrawal | H11: =PROPER('Transactions Overview'!H12) -> Utilities | I11: National Grid | J11: =PROPER('Transactions Overview'!J12) -> Cash | K11: Completed
A12: 108373 | B12: 45968 | C12: =PROPER('Transactions Overview'!C13) -> Credit Card | D12: =PROPER('Transactions Overview'!D13) -> Boston | E12: Massachusetts | F12: =ABS('Transactions Overview'!F13) -> 3060.68 | G12: Deposit | H12: =PROPER('Transactions Overview'!H13) -> Groceries | I12: Stop & Shop | J12: Wire Transfer | K12: Completed
A13: 102618 | B13: 45346 | C13: Credit Card | D13: =PROPER('Transactions Overview'!D14) -> Trenton | E13: New Jersey | F13: =ABS('Transactions Overview'!F14) -> 2562.89 | G13: Transfer | H13: =PROPER('Transactions Overview'!H14) -> Entertainment | I13: Hulu | J13: =PROPER('Transactions Overview'!J14) -> Cash | K13: Completed
A14: 105580 | B14: 45522 | C14: =PROPER('Transactions Overview'!C16) -> Checking | D14: =PROPER('Transactions Overview'!D16) -> Albany | E14: New York | F14: =ABS('Transactions Overview'!F16) -> 1344.25 | G14: Withdrawal | H14: =PROPER('Transactions Overview'!H16) -> Transportation | I14: EZ-Pass | J14: =PROPER('Transactions Overview'!J16) -> Check | K14: Completed
A15: 101092 | B15: 45096 | C15: =PROPER('Transactions Overview'!C17) -> Savings | D15: =PROPER('Transactions Overview'!D17) -> Trenton | E15: New Jersey | F15: =ABS('Transactions Overview'!F17) -> 133.77 | G15: Withdrawal | H15: =PROPER('Transactions Overview'!H17) -> Groceries | I15: Stop & Shop | J15: Wire Transfer | K15: Completed
A16: 104665 | B16: 45242 | C16: =PROPER('Transactions Overview'!C18) -> Checking | D16: =PROPER('Transactions Overview'!D18) -> Philadelphia | E16: Pennsylvania | F16: =ABS('Transactions Overview'!F18) -> 1958.72 | G16: Transfer | H16: =PROPER('Transactions Overview'!H18) -> Rent | I16: Rent Payment | J16: =PROPER('Transactions Overview'!J18) -> Cash | K16: Completed
A17: 104554 | B17: 46206 | C17: =PROPER('Transactions Overview'!C19) -> Credit Card | D17: =PROPER('Transactions Overview'!D19) -> Boston | E17: Massachusetts | F17: =ABS('Transactions Overview'!F19) -> 408.93 | G17: Payment | H17: Entertainment | I17: AMC Theatres | J17: =PROPER('Transactions Overview'!J19) -> Debit Card | K17: Completed
A18: 103646 | B18: 45608 | C18: =PROPER('Transactions Overview'!C20) -> Credit Card | D18: =PROPER('Transactions Overview'!D20) -> Philadelphia | E18: Pennsylvania | F18: =ABS('Transactions Overview'!F20) -> 1381.04 | G18: Withdrawal | H18: =PROPER('Transactions Overview'!H20) -> Groceries | I18: Costco | J18: =PROPER('Transactions Overview'!J20) -> Cash | K18: Completed
A19: 100837 | B19: 45166 | C19: Money Market | D19: =PROPER('Transactions Overview'!D21) -> Hartford | E19: Connecticut | F19: =ABS('Transactions Overview'!F21) -> 1783.21 | G19: Payment | H19: Income | I19: Payroll Deposit | J19: =PROPER('Transactions Overview'!J21) -> Debit Card | K19: Completed
A20: 105385 | B20: 44689 | C20: =PROPER('Transactions Overview'!C22) -> Credit Card | D20: =PROPER('Transactions Overview'!D22) -> Newark | E20: New Jersey | F20: =ABS('Transactions Overview'!F22) -> 2487.15 | G20: Transfer | H20: =PROPER('Transactions Overview'!H22) -> Transportation | I20: Uber | J20: Wire Transfer | K20: Pending
A21: 101831 | B21: 45582 | C21: =PROPER('Transactions Overview'!C23) -> Money Market | D21: =PROPER('Transactions Overview'!D23) -> Albany | E21: New York | F21: =ABS('Transactions Overview'!F23) -> 562.04 | G21: Deposit | H21: =PROPER('Transactions Overview'!H23) -> Groceries | I21: Whole Foods | J21: ACH | K21: Completed
A22: 107600 | B22: 45211 | C22: =PROPER('Transactions Overview'!C24) -> Money Market | D22: =PROPER('Transactions Overview'!D24) -> Albany | E22: New York | F22: =ABS('Transactions Overview'!F24) -> 1954.44 | G22: Deposit | H22: =PROPER('Transactions Overview'!H24) -> Dining | I22: Starbucks | J22: =PROPER('Transactions Overview'!J24) -> Check | K22: Completed
A23: 100828 | B23: 24/04/2022 | C23: =PROPER('Transactions Overview'!C25) -> Savings | D23: =PROPER('Transactions Overview'!D25) -> New York | E23: New York | F23: =ABS('Transactions Overview'!F25) -> 1624.61 | G23: Fee | H23: Fees | I23: Late Fee | J23: ACH | K23: Completed
A24: 102560 | B24: 46230 | C24: =PROPER('Transactions Overview'!C26) -> Money Market | D24: =PROPER('Transactions Overview'!D26) -> Brooklyn | E24: New York | F24: =ABS('Transactions Overview'!F26) -> 430.51 | G24: Payment | H24: =PROPER('Transactions Overview'!H26) -> Dining | I24: Starbucks | J24: =PROPER('Transactions Overview'!J26) -> Check | K24: Completed
A25: 102686 | B25: 45468 | C25: =PROPER('Transactions Overview'!C27) -> Money Market | D25: =PROPER('Transactions Overview'!D27) -> Jersey City | E25: New Jersey | F25: =ABS('Transactions Overview'!F27) -> 842.49 | G25: Payment | H25: =PROPER('Transactions Overview'!H27) -> Entertainment | I25: Hulu | J25: =PROPER('Transactions Overview'!J27) -> Check | K25: Completed
A26: 100504 | B26: 46056 | C26: =PROPER('Transactions Overview'!C28) -> Checking | D26: =PROPER('Transactions Overview'!D28) -> Boston | E26: Massachusetts | F26: =ABS('Transactions Overview'!F28) -> 1531.07 | G26: Fee | H26: =PROPER('Transactions Overview'!H28) -> Shopping | I26: Best Buy | J26: =PROPER('Transactions Overview'!J28) -> Debit Card | K26: Completed
A27: 104092 | B27: 45008 | C27: =PROPER('Transactions Overview'!C29) -> Checking | D27: =PROPER('Transactions Overview'!D29) -> Trenton | E27: New Jersey | F27: =ABS('Transactions Overview'!F29) -> 647.3 | G27: Withdrawal | H27: =PROPER('Transactions Overview'!H29) -> Transportation | I27: Shell Gas Station | J27: ACH | K27: Completed
A28: 106340 | B28: 45341 | C28: =PROPER('Transactions Overview'!C30) -> Money Market | D28: =PROPER('Transactions Overview'!D30) -> Trenton | E28: New Jersey | F28: =ABS('Transactions Overview'!F30) -> 118.5 | G28: Deposit | H28: =PROPER('Transactions Overview'!H30) -> Dining | I28: Chipotle | J28: =PROPER('Transactions Overview'!J30) -> Credit Card | K28: Completed
A29: 105305 | B29: 45571 | C29: =PROPER('Transactions Overview'!C32) -> Checking | D29: =PROPER('Transactions Overview'!D32) -> Boston | E29: Massachusetts | F29: =ABS('Transactions Overview'!F32) -> 821.76 | G29: Payment | H29: =PROPER('Transactions Overview'!H32) -> Entertainment | I29: Steam | J29: =PROPER('Transactions Overview'!J32) | K29: Completed
A30: 108240 | B30: 46117 | C30: =PROPER('Transactions Overview'!C33) -> Money Market | D30: =PROPER('Transactions Overview'!D33) -> Philadelphia | E30: Pennsylvania | F30: =ABS('Transactions Overview'!F33) -> 1601.03 | G30: Payment | H30: =PROPER('Transactions Overview'!H33) -> Entertainment | I30: Netflix | J30: Check | K30: Completed
A31: 100840 | B31: 44690 | C31: =PROPER('Transactions Overview'!C34) -> Credit Card | D31: =PROPER('Transactions Overview'!D34) -> Trenton | E31: New Jersey | F31: =ABS('Transactions Overview'!F34) -> 219.92 | G31: Withdrawal | H31: =PROPER('Transactions Overview'!H34) -> Dining | I31: Chipotle | J31: ACH | K31: Completed
A32: 108931 | B32: 45608 | C32: =PROPER('Transactions Overview'!C36) -> Savings | D32: =PROPER('Transactions Overview'!D36) -> Philadelphia | E32: Pennsylvania | F32: =ABS('Transactions Overview'!F36) -> 685.09 | G32: Payment | H32: =PROPER('Transactions Overview'!H36) -> Shopping | I32: Walmart | J32: Wire Transfer | K32: Completed
A33: 101832 | B33: 44974 | C33: =PROPER('Transactions Overview'!C37) -> Money Market | D33: =PROPER('Transactions Overview'!D37) -> Albany | E33: New York | F33: =ABS('Transactions Overview'!F37) -> 326.64 | G33: Withdrawal | H33: =PROPER('Transactions Overview'!H37) -> Healthcare | I33: Walgreens | J33: ACH | K33: Pending
A34: 105588 | B34: 44671 | C34: =PROPER('Transactions Overview'!C38) -> Checking | D34: =PROPER('Transactions Overview'!D38) -> Albany | E34: New York | F34: =ABS('Transactions Overview'!F38) -> 2788.39 | G34: Payment | H34: =PROPER('Transactions Overview'!H38) -> Insurance | I34: State Farm | J34: ACH | K34: Completed
A35: 101703 | B35: 45556 | C35: Credit Card | D35: =PROPER('Transactions Overview'!D39) -> New York | E35: New York | F35: =ABS('Transactions Overview'!F39) -> 2600.4 | G35: Payment | H35: =PROPER('Transactions Overview'!H39) -> Shopping | I35: Target | J35: Debit Card | K35: Completed
A36: 102630 | B36: 44912 | C36: =PROPER('Transactions Overview'!C40) -> Credit Card | D36: =PROPER('Transactions Overview'!D40) -> Philadelphia | E36: Pennsylvania | F36: =ABS('Transactions Overview'!F40) -> 2251.77 | G36: Fee | H36: Fees | I36: ATM Fee | J36: =PROPER('Transactions Overview'!J40) -> Credit Card | K36: Completed
A37: 108467 | B37: 44984 | C37: =PROPER('Transactions Overview'!C41) -> Money Market | D37: =PROPER('Transactions Overview'!D41) -> Albany | E37: New York | F37: =ABS('Transactions Overview'!F41) -> 964.9 | G37: Withdrawal | H37: =PROPER('Transactions Overview'!H41) -> Healthcare | I37: Copay - Dr. Visit | J37: =PROPER('Transactions Overview'!J41) -> Wire Transfer | K37: Completed
A38: 107547 | B38: 46077 | C38: =PROPER('Transactions Overview'!C42) -> Credit Card | D38: =PROPER('Transactions Overview'!D42) -> Trenton | E38: New Jersey | F38: =ABS('Transactions Overview'!F42) -> 2840.57 | G38: Payment | H38: Transfers | I38: Zelle Transfer | J38: =PROPER('Transactions Overview'!J42) -> Cash | K38: Completed
A39: 100499 | B39: 46178 | C39: =PROPER('Transactions Overview'!C44) -> Money Market | D39: =PROPER('Transactions Overview'!D44) -> Albany | E39: New York | F39: =ABS('Transactions Overview'!F44) -> 393.53 | G39: Payment | H39: =PROPER('Transactions Overview'!H44) -> Insurance | I39: Geico | J39: Wire Transfer | K39: Completed
A40: 102987 | B40: 45826 | C40: =PROPER('Transactions Overview'!C45) -> Money Market | D40: =PROPER('Transactions Overview'!D45) -> Stamford | E40: Connecticut | F40: =ABS('Transactions Overview'!F45) -> 2529.06 | G40: Deposit | H40: =PROPER('Transactions Overview'!H45) -> Groceries | I40: Trader Joe's | J40: ACH | K40: Completed
...

Sheet Transactions (Cleaned)
A1: transaction_id | B1: transaction_date | C1: account_type | D1: branch_city | E1: branch_state | F1: amount | G1: transaction_type | H1: category | I1: merchant | J1: payment_method | K1: status
A2: 106499 | B2: 45992 | C2: Money Market | D2: Albany | E2: New York | F2: 2282.09 | G2: Payment | H2: Transportation | I2: EZ-Pass | J2: Wire Transfer | K2: Completed
A3: 101635 | B3: 45715 | C3: Savings | D3: Philadelphia | E3: Pennsylvania | F3: 431.86 | G3: Transfer | H3: Transportation | I3: Lyft | K3: Pending
A4: 102938 | B4: 45443 | C4: Checking | D4: Stamford | E4: Connecticut | F4: 277.69 | G4: Transfer | H4: Shopping | I4: Amazon | J4: Cash | K4: Completed
A5: 110478 | B5: 44762 | C5: Credit Card | D5: New York | E5: New York | F5: 2999.37 | G5: Transfer | H5: Shopping | I5: Target | J5: Cash | K5: Completed
A6: 100906 | B6: 45254 | C6: Savings | D6: Hartford | E6: Connecticut | F6: 1087.05 | G6: Withdrawal | H6: Fees | I6: Late Fee | J6: Cash | K6: Completed
A7: 104027 | B7: 45903 | C7: Money Market | D7: Jersey City | E7: New Jersey | F7: 102.75 | G7: Withdrawal | H7: Utilities | I7: PSEG | J7: Debit Card | K7: Pending
A8: 105516 | B8: 45794 | C8: Credit Card | D8: New York | E8: New York | F8: 1605.73 | G8: Fee | H8: Rent | I8: Rent Payment | J8: Cash | K8: Completed
A9: 108794 | B9: 45906 | C9: Credit Card | D9: Newark | E9: New Jersey | F9: 486.99 | G9: Deposit | H9: Fees | I9: Late Fee | J9: Debit Card | K9: Completed
A10: 107911 | B10: 44687 | C10: Checking | D10: Philadelphia | E10: Pennsylvania | F10: 1844.79 | G10: Payment | H10: Fees | I10: Late Fee | J10: Cash | K10: Completed
A11: 105279 | B11: 45774 | C11: Money Market | D11: Hicksville | E11: New York | F11: 2495.04 | G11: Withdrawal | H11: Utilities | I11: National Grid | J11: Cash | K11: Completed
A12: 108373 | B12: 45968 | C12: Credit Card | D12: Boston | E12: Massachusetts | F12: 3060.68 | G12: Deposit | H12: Groceries | I12: Stop & Shop | J12: Wire Transfer | K12: Completed
A13: 102618 | B13: 45346 | C13: Credit Card | D13: Trenton | E13: New Jersey | F13: 2562.89 | G13: Transfer | H13: Entertainment | I13: Hulu | J13: Cash | K13: Completed
A14: 105580 | B14: 45522 | C14: Checking | D14: Albany | E14: New York | F14: 1344.25 | G14: Withdrawal | H14: Transportation | I14: EZ-Pass | J14: Check | K14: Completed
A15: 101092 | B15: 45096 | C15: Savings | D15: Trenton | E15: New Jersey | F15: 133.77 | G15: Withdrawal | H15: Groceries | I15: Stop & Shop | J15: Wire Transfer | K15: Completed
... A28: 106340 | B28: 45341 | C28: Money Market | D28: Trenton | E28: New Jersey | F28: 118.5 | G28: Deposit | H28: Dining | I28: Chipotle | J28: Credit Card | K28: Completed
A29: 105305 | B29: 45571 | C29: Checking | D29: Boston | E29: Massachusetts | F29: 821.76 | G29: Payment | H29: Entertainment | I29: Steam | K29: Completed
A30: 108240 | B30: 46117 | C30: Money Market | D30: Philadelphia | E30: Pennsylvania | F30: 1601.03 | G30: Payment | H30: Entertainment | I30: Netflix | J30: Check | K30: Completed
A31: 100840 | B31: 44690 | C31: Credit Card | D31: Trenton | E31: New Jersey | F31: 219.92 | G31: Withdrawal | H31: Dining | I31: Chipotle | J31: ACH | K31: Completed
A32: 108931 | B32: 45608 | C32: Savings | D32: Philadelphia | E32: Pennsylvania | F32: 685.09 | G32: Payment | H32: Shopping | I32: Walmart | J32: Wire Transfer | K32: Completed
A33: 101832 | B33: 44974 | C33: Money Market | D33: Albany | E33: New York | F33: 326.64 | G33: Withdrawal | H33: Healthcare | I33: Walgreens | J33: ACH | K33: Pending
A34: 105588 | B34: 44671 | C34: Checking | D34: Albany | E34: New York | F34: 2788.39 | G34: Payment | H34: Insurance | I34: State Farm | J34: ACH | K34: Completed
A35: 101703 | B35: 45556 | C35: Credit Card | D35: New York | E35: New York | F35: 2600.4 | G35: Payment | H35: Shopping | I35: Target | J35: Debit Card | K35: Completed
A36: 102630 | B36: 44912 | C36: Credit Card | D36: Philadelphia | E36: Pennsylvania | F36: 2251.77 | G36: Fee | H36: Fees | I36: ATM Fee | J36: Credit Card | K36: Completed
A37: 108467 | B37: 44984 | C37: Money Market | D37: Albany | E37: New York | F37: 964.9 | G37: Withdrawal | H37: Healthcare | I37: Copay - Dr. Visit | J37: Wire Transfer | K37: Completed
A38: 107547 | B38: 46077 | C38: Credit Card | D38: Trenton | E38: New Jersey | F38: 2840.57 | G38: Payment | H38: Transfers | I38: Zelle Transfer | J38: Cash | K38: Completed
A39: 100499 | B39: 46178 | C39: Money Market | D39: Albany | E39: New York | F39: 393.53 | G39: Payment | H39: Insurance | I39: Geico | J39: Wire Transfer | K39: Completed
A40: 102987 | B40: 45826 | C40: Money Market | D40: Stamford | E40: Connecticut | F40: 2529.06 | G40: Deposit | H40: Groceries | I40: Trader Joe's | J40: ACH | K40: Completed
A41: 101550 | B41: 46254 | C41: Checking | D41: Philadelphia | E41: Pennsylvania | F41: 303.04 | G41: Withdrawal | H41: Shopping | I41: Best Buy | J41: Cash | K41: Completed
... A49: 109805 | B49: 45867 | C49: Money Market | D49: Albany | E49: New York | F49: 3055.5 | G49: Transfer | H49: Healthcare | I49: Copay - Dr. Visit | J49: Check | K49: Completed
A50: 103004 | B50: 45388 | C50: Savings | D50: New York | E50: New York | F50: 1219.92 | G50: Transfer | H50: Healthcare | J50: Cash | K50: Completed
A51: 103330 | B51: 45860 | C51: Savings | D51: Trenton | E51: New Jersey | F51: 2618.76 | G51: Fee | H51: Fees | I51: ATM Fee | J51: Credit Card | K51: Completed
A52: 101632 | B52: 45261 | C52: Savings | D52: Newark | E52: New Jersey | F52: 2901.12 | G52: Payment | H52: Dining | I52: Local Diner | J52: Cash | K52: Completed
A53: 102146 | B53: 45305 | C53: Checking | D53: Trenton | E53: New Jersey | F53: 3004.07 | G53: Deposit | H53: Transfers | I53: Zelle Transfer | J53: Cash | K53: Completed
A54: 103451 | B54: 44657 | C54: Savings | D54: Albany | E54: New York | F54: 760.84 | G54: Withdrawal | H54: Healthcare | J54: ACH | K54: Completed
A55: 106969 | B55: 45097 | C55: Credit Card | D55: Albany | E55: New York | F55: 883.46 | G55: Deposit | H55: Insurance | I55: Geico | J55: Check | K55: Completed
A56: 108191 | B56: 45150 | C56: Money Market | D56: New York | E56: New York | F56: 2262.11 | G56: Payment | H56: Transfers | I56: Internal Transfer | J56: Wire Transfer | K56: Failed
A57: 106446 | B57: 44803 | C57: Credit Card | D57: Trenton | E57: New Jersey | F57: 2134.87 | G57: Transfer | H57: Entertainment | I57: AMC Theatres | J57: ACH | K57: Completed
A58: 102187 | B58: 44752 | C58: Money Market | D58: Hartford | E58: Connecticut | F58: 2268.98 | G58: Transfer | H58: Shopping | I58: Target | J58: Wire Transfer | K58: Completed
A59: 100608 | B59: 45702 | C59: Credit Card | D59: Boston | E59: Massachusetts | F59: 566.37 | G59: Withdrawal | H59: Utilities | I59: PSEG | J59: Cash | K59: Completed
...
