Workbook

Sheet finance_joined_tables
A1: account_id | B1: credit_score | C1: account_status | D1: transaction_id | E1: transaction_date | F1: category | G1: transaction_type | H1: payment_method | I1: status
A2: NULL | B2: NULL | C2: NULL | D2: 100001 | E2: 44700 | F2: fees | G2: Fee | H2: ach | I2: Completed
A3: 10357 | B3: 734 | C3: Active | D3: 100002 | E3: 45670 | F3: UTILITIES | G3: Payment | H3: CREDIT CARD | I3: Completed
A4: 10140 | B4: 600 | C4: Active | D4: 100003 | E4: 45873 | F4: Entertainmnt | G4: Payment | H4: ach | I4: Completed
A5: 10049 | B5: 765 | C5: Active | D5: 100004 | E5: 28/03/2022 | F5: Healthcare | G5: Payment | H5: Credit | I5: Completed
A6: 10544 | B6: 452 | C6: Closed | D6: 100005 | E6: 44853 | F6: salary | G6: Deposit | H6: ACH | I6: Completed
A7: 10415 | B7: 307 | C7: Active | D7: 100006 | E7: 45949 | F7: Utilities | G7: Payment | H7: DEBIT CARD | I7: Completed
A8: 10481 | B8: 331 | C8: Active | D8: 100007 | E8: 25/09/2022 | F8: ENTERTAINMENT | G8: Payment | H8: Debit | I8: Failed
A9: 10519 | B9: 363 | C9: Active | D9: 100008 | E9: 44820 | F9: insurance | G9: Payment | H9: Credit Card | I9: Completed
A10: 10560 | B10: 602 | C10: Active | D10: 100009 | E10: 45327 | F10: insurance | G10: Payment | H10: CHECK | I10: Completed
A11: 10328 | B11: 620 | C11: Active | D11: 100010 | E11: 44883 | F11: Dining | G11: Withdrawal | H11: DEBIT CARD | I11: Completed
A12: 10636 | B12: 756 | C12: Active | D12: 100011 | E12: 44929 | F12: Health Care | G12: Payment | H12: Check | I12: Completed
A13: 10437 | B13: 335 | C13: Active | D13: 100012 | E13: 45088 | F13: SALARY | G13: Deposit | H13: ach | I13: Completed
A14: NULL | B14: NULL | C14: NULL | D14: 100013 | E14: 15/11/2024 | F14: utilities | G14: Payment | H14: Debit | I14: Completed
A15: 10385 | B15: 679 | C15: Active | D15: 100014 | E15: 45080 | F15: Healthcare | G15: Payment | H15: credit card | I15: Completed
A16: 10168 | B16: 319 | C16: Active | D16: 100015 | E16: 44609 | F16: fees | G16: Fee | H16: ach | I16: Failed
A17: 10447 | B17: 387 | C17: Active | D17: 100016 | E17: 45694 | F17: UTILITIES | G17: Payment | H17: debit card | I17: Completed
A18: 10624 | B18: 640 | C18: Active | D18: 100017 | E18: 45362 | F18: utilities | G18: Payment | H18: Check | I18: Completed
A19: 10231 | B19: 419 | C19: Active | D19: 100018 | E19: 26/10/2024 | F19: shopping | G19: Payment | H19: debit card | I19: Completed
A20: 10249 | B20: 659 | C20: Active | D20: 100019 | E20: 45496 | F20: DINING | G20: Withdrawal | H20: credit card | I20: Completed
A21: 10459 | B21: 682 | C21: Active | D21: 100020 | E21: 45122 | F21: TRANSFER | G21: Transfer | H21: ach | I21: Completed
A22: 10334 | B22: 780 | C22: Closed | D22: 100021 | E22: 44616 | F22: Rent Payment | G22: Payment | H22: Wire Transfer | I22: Completed
A23: 10061 | B23: 837 | C23: Frozen | D23: 100022 | E23: 46023 | F23: HEALTHCARE | G23: Payment | H23: credit card | I23: Completed
A24: NULL | B24: NULL | C24: NULL | D24: 100023 | E24: 44876 | F24: healthcare | G24: Payment | H24: debit card | I24: Completed
A25: 10648 | B25: 319 | C25: Active | D25: 100024 | E25: 46133 | F25: Entertainmnt | G25: Payment | H25: Credit Card | I25: Completed
A26: 10375 | B26: 826 | C26: Active | D26: 100025 | E26: 45413 | F26: insurance | G26: Payment | H26: credit card | I26: Completed
A27: 10402 | B27: 710 | C27: Active | D27: 100026 | E27: 45012 | F27: RENT | G27: Payment | H27: check | I27: Completed
A28: 10065 | B28: 753 | C28: Active | D28: 100027 | E28: 45988 | F28: Transport | G28: Withdrawal | H28: CASH | I28: Completed
A29: 10458 | B29: 573 | C29: Active | D29: 100028 | E29: 44589 | F29: Entertainment | G29: Payment | H29: Credit | I29: Completed
A30: 10648 | B30: 319 | C30: Active | D30: 100029 | E30: 45235 | F30: Utility | G30: Payment | H30: CHECK | I30: Completed
A31: 10513 | B31: 568 | C31: Closed | D31: 100030 | E31: 45343 | F31: Insurance | G31: Payment | H31: Credit Card | I31: Completed
A32: 10271 | B32: 714 | C32: Active | D32: 100031 | E32: 46046 | F32: healthcare | G32: Payment | H32: Credit | I32: Completed
A33: 10293 | B33: 696 | C33: Closed | D33: 100032 | E33: 22/06/2024 | F33: TRANSPORTATION | G33: Withdrawal | H33: Credit Card | I33: Completed
A34: NULL | B34: NULL | C34: NULL | D34: 100033 | E34: 45330 | F34: insurance | G34: Payment | H34: check | I34: Completed
A35: 10178 | B35: 497 | C35: Active | D35: 100034 | E35: 45564 | F35: Payroll | G35: Deposit | H35: ach | I35: Pending
A36: 10436 | B36: 631 | C36: Active | D36: 100035 | E36: 45430 | F36: Shopping | G36: Withdrawal | H36: DEBIT CARD | I36: Completed
A37: NULL | B37: NULL | C37: NULL | D37: 100036 | E37: 46140 | F37: Rent Payment | G37: Payment | H37: wire | I37: Completed
A38: 10471 | B38: 448 | C38: Active | D38: 100037 | E38: 44744 | F38: rent | G38: Payment | I38: Pending
A39: NULL | B39: NULL | C39: NULL | D39: 100038 | E39: 45444 | F39: Utility | G39: Payment | H39: debit card | I39: Completed
A40: 10468 | B40: 756 | C40: Active | D40: 100039 | E40: 45399 | F40: healthcare | G40: Payment | H40: Check | I40: Completed
...

Sheet finance_joined_tables (2)
A1: account_id | B1: credit_score | C1: account_status | D1: transaction_id | E1: transaction_date | F1: category | G1: transaction_type | H1: payment_method | I1: status
A2: NULL | B2: NULL | C2: NULL | D2: 100001 | E2: 44700 | F2: =PROPER(finance_joined_tables!F2) -> Fees | G2: Fee | H2: ACH | I2: Completed
A3: 10357 | B3: 734 | C3: Active | D3: 100002 | E3: 45670 | F3: =PROPER(finance_joined_tables!F3) -> Utilities | G3: Payment | H3: =PROPER(finance_joined_tables!H3) -> Credit Card | I3: Completed
A4: 10140 | B4: 600 | C4: Active | D4: 100003 | E4: 45873 | F4: Entertainment | G4: Payment | H4: ACH | I4: Completed
A5: 10049 | B5: 765 | C5: Active | D5: 100004 | E5: 28/03/2022 | F5: =PROPER(finance_joined_tables!F5) -> Healthcare | G5: Payment | H5: Credit Card | I5: Completed
A6: 10544 | B6: 452 | C6: Closed | D6: 100005 | E6: 44853 | F6: Payroll/Salary | G6: Deposit | H6: ACH | I6: Completed
A7: 10415 | B7: 307 | C7: Active | D7: 100006 | E7: 45949 | F7: =PROPER(finance_joined_tables!F7) -> Utilities | G7: Payment | H7: =PROPER(finance_joined_tables!H7) -> Debit Card | I7: Completed
A8: 10481 | B8: 331 | C8: Active | D8: 100007 | E8: 25/09/2022 | F8: =PROPER(finance_joined_tables!F8) -> Entertainment | G8: Payment | H8: Debit Card | I8: Failed
A9: 10519 | B9: 363 | C9: Active | D9: 100008 | E9: 44820 | F9: =PROPER(finance_joined_tables!F9) -> Insurance | G9: Payment | H9: =PROPER(finance_joined_tables!H9) -> Credit Card | I9: Completed
A10: 10560 | B10: 602 | C10: Active | D10: 100009 | E10: 45327 | F10: =PROPER(finance_joined_tables!F10) -> Insurance | G10: Payment | H10: =PROPER(finance_joined_tables!H10) -> Check | I10: Completed
A11: 10328 | B11: 620 | C11: Active | D11: 100010 | E11: 44883 | F11: =PROPER(finance_joined_tables!F11) -> Dining | G11: Withdrawal | H11: =PROPER(finance_joined_tables!H11) -> Debit Card | I11: Completed
A12: 10636 | B12: 756 | C12: Active | D12: 100011 | E12: 44929 | F12: Healthcare | G12: Payment | H12: =PROPER(finance_joined_tables!H12) -> Check | I12: Completed
A13: 10437 | B13: 335 | C13: Active | D13: 100012 | E13: 45088 | F13: Payroll/Salary | G13: Deposit | H13: ACH | I13: Completed
A14: NULL | B14: NULL | C14: NULL | D14: 100013 | E14: 15/11/2024 | F14: =PROPER(finance_joined_tables!F14) -> Utilities | G14: Payment | H14: Debit Card | I14: Completed
A15: 10385 | B15: 679 | C15: Active | D15: 100014 | E15: 45080 | F15: =PROPER(finance_joined_tables!F15) -> Healthcare | G15: Payment | H15: =PROPER(finance_joined_tables!H15) -> Credit Card | I15: Completed
A16: 10168 | B16: 319 | C16: Active | D16: 100015 | E16: 44609 | F16: =PROPER(finance_joined_tables!F16) -> Fees | G16: Fee | H16: ACH | I16: Failed
A17: 10447 | B17: 387 | C17: Active | D17: 100016 | E17: 45694 | F17: =PROPER(finance_joined_tables!F17) -> Utilities | G17: Payment | H17: =PROPER(finance_joined_tables!H17) -> Debit Card | I17: Completed
A18: 10624 | B18: 640 | C18: Active | D18: 100017 | E18: 45362 | F18: =PROPER(finance_joined_tables!F18) -> Utilities | G18: Payment | H18: =PROPER(finance_joined_tables!H18) -> Check | I18: Completed
A19: 10231 | B19: 419 | C19: Active | D19: 100018 | E19: 26/10/2024 | F19: =PROPER(finance_joined_tables!F19) -> Shopping | G19: Payment | H19: =PROPER(finance_joined_tables!H19) -> Debit Card | I19: Completed
A20: 10249 | B20: 659 | C20: Active | D20: 100019 | E20: 45496 | F20: =PROPER(finance_joined_tables!F20) -> Dining | G20: Withdrawal | H20: =PROPER(finance_joined_tables!H20) -> Credit Card | I20: Completed
A21: 10459 | B21: 682 | C21: Active | D21: 100020 | E21: 45122 | F21: Transfers | G21: Transfer | H21: ACH | I21: Completed
A22: 10334 | B22: 780 | C22: Closed | D22: 100021 | E22: 44616 | F22: Rent | G22: Payment | H22: =PROPER(finance_joined_tables!H22) -> Wire Transfer | I22: Completed
A23: 10061 | B23: 837 | C23: Frozen | D23: 100022 | E23: 46023 | F23: =PROPER(finance_joined_tables!F23) -> Healthcare | G23: Payment | H23: =PROPER(finance_joined_tables!H23) -> Credit Card | I23: Completed
A24: NULL | B24: NULL | C24: NULL | D24: 100023 | E24: 44876 | F24: =PROPER(finance_joined_tables!F24) -> Healthcare | G24: Payment | H24: =PROPER(finance_joined_tables!H24) -> Debit Card | I24: Completed
A25: 10648 | B25: 319 | C25: Active | D25: 100024 | E25: 46133 | F25: Entertainment | G25: Payment | H25: =PROPER(finance_joined_tables!H25) -> Credit Card | I25: Completed
A26: 10375 | B26: 826 | C26: Active | D26: 100025 | E26: 45413 | F26: =PROPER(finance_joined_tables!F26) -> Insurance | G26: Payment | H26: =PROPER(finance_joined_tables!H26) -> Credit Card | I26: Completed
A27: 10402 | B27: 710 | C27: Active | D27: 100026 | E27: 45012 | F27: =PROPER(finance_joined_tables!F27) -> Rent | G27: Payment | H27: =PROPER(finance_joined_tables!H27) -> Check | I27: Completed
A28: 10065 | B28: 753 | C28: Active | D28: 100027 | E28: 45988 | F28: Transportation | G28: Withdrawal | H28: =PROPER(finance_joined_tables!H28) -> Cash | I28: Completed
A29: 10458 | B29: 573 | C29: Active | D29: 100028 | E29: 44589 | F29: =PROPER(finance_joined_tables!F29) -> Entertainment | G29: Payment | H29: Credit Card | I29: Completed
A30: 10648 | B30: 319 | C30: Active | D30: 100029 | E30: 45235 | F30: Utilities | G30: Payment | H30: =PROPER(finance_joined_tables!H30) -> Check | I30: Completed
A31: 10513 | B31: 568 | C31: Closed | D31: 100030 | E31: 45343 | F31: =PROPER(finance_joined_tables!F31) -> Insurance | G31: Payment | H31: =PROPER(finance_joined_tables!H31) -> Credit Card | I31: Completed
A32: 10271 | B32: 714 | C32: Active | D32: 100031 | E32: 46046 | F32: =PROPER(finance_joined_tables!F32) -> Healthcare | G32: Payment | H32: Credit Card | I32: Completed
A33: 10293 | B33: 696 | C33: Closed | D33: 100032 | E33: 22/06/2024 | F33: =PROPER(finance_joined_tables!F33) -> Transportation | G33: Withdrawal | H33: =PROPER(finance_joined_tables!H33) -> Credit Card | I33: Completed
A34: NULL | B34: NULL | C34: NULL | D34: 100033 | E34: 45330 | F34: =PROPER(finance_joined_tables!F34) -> Insurance | G34: Payment | H34: =PROPER(finance_joined_tables!H34) -> Check | I34: Completed
A35: 10178 | B35: 497 | C35: Active | D35: 100034 | E35: 45564 | F35: Payroll/Salary | G35: Deposit | H35: ACH | I35: Pending
A36: 10436 | B36: 631 | C36: Active | D36: 100035 | E36: 45430 | F36: =PROPER(finance_joined_tables!F36) -> Shopping | G36: Withdrawal | H36: =PROPER(finance_joined_tables!H36) -> Debit Card | I36: Completed
A37: NULL | B37: NULL | C37: NULL | D37: 100036 | E37: 46140 | F37: Rent | G37: Payment | H37: Wire Transfer | I37: Completed
A38: 10471 | B38: 448 | C38: Active | D38: 100037 | E38: 44744 | F38: =PROPER(finance_joined_tables!F38) -> Rent | G38: Payment | H38: =PROPER(finance_joined_tables!H38) | I38: Pending
A39: NULL | B39: NULL | C39: NULL | D39: 100038 | E39: 45444 | F39: Utilities | G39: Payment | H39: =PROPER(finance_joined_tables!H39) -> Debit Card | I39: Completed
A40: 10468 | B40: 756 | C40: Active | D40: 100039 | E40: 45399 | F40: =PROPER(finance_joined_tables!F40) -> Healthcare | G40: Payment | H40: =PROPER(finance_joined_tables!H40) -> Check | I40: Completed
...
